jest.mock("../util/errors.ts", () => ({ catchErrors: jest.fn() }));

import * as React from "react";
import { mount, ReactWrapper } from "enzyme";
import { ErrorBoundary } from "../error_boundary";
import { catchErrors } from "../util";

class Kaboom extends React.Component<{}, {}> {
  TRUE = (1 + 1) === 2;

  render() {
    if (this.TRUE) {
      throw new Error("ALWAYS");
    } else {
      return <div />;
    }
  }
}

describe("<ErrorBoundary/>", () => {
  it("handles exceptions", () => {
    const nodes = <ErrorBoundary><Kaboom /></ErrorBoundary>;
    type X = ReactWrapper<{}, ErrorBoundary["state"]>;
    const el: X = mount(nodes);
    expect(el.text()).toContain("can't render this part of the page");
    const i = el.instance();
    expect(i.state.hasError).toBe(true);
    expect(catchErrors).toHaveBeenCalled();
  });
});
